<?xml version="1.0"?>
<robot name="aiibot">
	<link name="base_link">
		<visual>
			<geometry>
				<box size="0.52 0.466 .003"/>
			</geometry>
			<origin rpy="0 0 0" xyz="-0.14 0 0"/>
			<material name="gray">
				<color rgba="0.6 0.6 0.6 1"/>
			</material>
		</visual>
 	</link>

<!--  	<link name="base_link_back">
		<visual>
			<geometry>
				<cylinder length="0.003" radius="0.233"/>
			</geometry>
			<material name="gray">
				<color rgba="0.6 0.6 0.6 1"/>
			</material>
		</visual>
	</link>

	<joint name="base_link_back_joint" type="fixed">
		<axis xyz="0 0 1"/>
		<parent link="base_link"/>
		<child link="base_link_back"/>
		<origin rpy="0 0 0" xyz="-0.33 0 0"/>
		<limit effort="100" velocity="100"/>
		<joint_properties damping="0.0" friction="0.0"/>
	</joint> -->

 	<link name="right_front_wheel">
		<visual>
			<geometry>
				<cylinder length="0.013" radius="0.049"/>
			</geometry>
			<material name="black">
				<color rgba="0 0 0 1"/>
			</material>
		</visual>
	</link>

	<joint name="right_front_wheel_joint" type="continuous">
		<axis xyz="0 0 1"/>
		<parent link="base_link"/>
		<child link="right_front_wheel"/>
		<origin rpy="0 1.57075 1.57075" xyz="0 -0.24 -0.025"/>
		<limit effort="100" velocity="100"/>
		<joint_properties damping="0.0" friction="0.0"/>
	</joint>


 	<link name="left_front_wheel">
		<visual>
			<geometry>
				<cylinder length="0.013" radius="0.049"/>
			</geometry>
			<material name="black">
				<color rgba="0 0 0 1"/>
			</material>
		</visual>
	</link>

	<joint name="left_front_wheel_joint" type="continuous">
		<axis xyz="0 0 1"/>
		<parent link="base_link"/>
		<child link="left_front_wheel"/>
		<origin rpy="0 1.57075 1.57075" xyz="0 0.24 -0.025"/>
		<limit effort="100" velocity="100"/>
		<joint_properties damping="0.0" friction="0.0"/>
	</joint>

	<link name="back_wheel_base">
		<visual>
			<geometry>
				<box size="0.04 0.04 0.04"/>
			</geometry>
		<material name="white">
			<color rgba="0.6 0.6 0.6 1"/>
		</material>
		</visual>
	</link>

	<joint name="back_wheel_base_joint" type="fixed">
		<parent link="base_link"/>
		<child link="back_wheel_base"/>
		<origin xyz="-0.35 0 -0.02"/>
	</joint>

	<link name="back_wheel">
		<visual>
			<geometry>
				<cylinder length=".02" radius="0.027"/>
			</geometry>
			<material name="white">
				<color rgba="1.0 1.0 1.0 1.0"/>
			</material>
		</visual>
	</link>

	<joint name="back_wheel_joint" type="continuous">
		<axis xyz="0 0 1"/>
		<parent link="back_wheel_base"/>
		<child link="back_wheel"/>
		<origin rpy="0 1.57075 1.57075" xyz="0 0 -0.027"/>
		<limit effort="100" velocity="100"/>
		<joint_properties damping="0.0" friction="0.0"/>
	</joint>

	<link name="laser">
		<visual>
			<geometry>
				<cylinder length="0.03" radius="0.035"/>
			</geometry>
		<material name="black">
			<color rgba="0 0 0 1"/>
		</material>
		</visual>
	</link>

	<joint name="base_liser_joint" type="fixed">
		<parent link="base_link"/>
		<child link="laser"/>
		<origin xyz="-0.250 0 0.2" rpy="0 0 3.1415927" />
	</joint>

	<link name="shelf_left">
		<visual>
			<geometry>
				<box size="0.25 0.002 .08"/>
			</geometry>
			<origin rpy="0 0 0" xyz="0 0 0"/>
			<material name="gray">
				<color rgba="0.6 0.6 0.6 1"/>
			</material>
		</visual>
 	</link>

	<joint name="shelf_left_joint" type="continuous">
		<axis xyz="0 0 1"/>
		<parent link="base_link"/>
		<child link="shelf_left"/>
		<origin rpy="0 0 0" xyz="-0.13 -0.149 0.04"/>
		<limit effort="100" velocity="100"/>
		<joint_properties damping="0.0" friction="0.0"/>
	</joint>
	<link name="shelf_right">
		<visual>
			<geometry>
				<box size="0.25 0.002 .08"/>
			</geometry>
			<origin rpy="0 0 0" xyz="0 0 0"/>
			<material name="gray">
				<color rgba="0.6 0.6 0.6 1"/>
			</material>
		</visual>
 	</link>

	<joint name="shelf_right_joint" type="continuous">
		<axis xyz="0 0 1"/>
		<parent link="base_link"/>
		<child link="shelf_right"/>
		<origin rpy="0 0 0" xyz="-0.13 0.149 0.04"/>
		<limit effort="100" velocity="100"/>
		<joint_properties damping="0.0" friction="0.0"/>
	</joint>
	<link name="shelf_top">
		<visual>
			<geometry>
				<box size="0.25 0.3 .002"/>
			</geometry>
			<origin rpy="0 0 0" xyz="0 0 0"/>
			<material name="gray">
				<color rgba="0.6 0.6 0.6 1"/>
			</material>
		</visual>
 	</link>

	<joint name="shelf_top_joint" type="continuous">
		<axis xyz="0 0 1"/>
		<parent link="base_link"/>
		<child link="shelf_top"/>
		<origin rpy="0 0 0" xyz="-0.13 0 0.08"/>
		<limit effort="100" velocity="100"/>
		<joint_properties damping="0.0" friction="0.0"/>
	</joint>

	<link name="shelf_lidar_front">
		<visual>
			<geometry>
				<box size="0.002 0.1 .08"/>
			</geometry>
			<origin rpy="0 0 0" xyz="0 0 0"/>
			<material name="gray">
				<color rgba="0.6 0.6 0.6 1"/>
			</material>
		</visual>
 	</link>

	<joint name="shelf_lidar_front_joint" type="continuous">
		<axis xyz="0 0 1"/>
		<parent link="base_link"/>
		<child link="shelf_lidar_front"/>
		<origin rpy="0 0 0" xyz="-0.041 0 0.12"/>
		<limit effort="100" velocity="100"/>
		<joint_properties damping="0.0" friction="0.0"/>
	</joint> 

	<link name="shelf_lidar_top">
		<visual>
			<geometry>
				<box size="0.1 0.1 .002"/>
			</geometry>
			<origin rpy="0 0 0" xyz="0 0 0"/>
			<material name="gray">
				<color rgba="0.6 0.6 0.6 1"/>
			</material>
		</visual>
 	</link>

	<joint name="shelf_lidar_top_joint" type="continuous">
		<axis xyz="0 0 1"/>
		<parent link="base_link"/>
		<child link="shelf_lidar_top"/>
		<origin rpy="0 0 0" xyz="-0.09 0 0.16"/>
		<limit effort="100" velocity="100"/>
		<joint_properties damping="0.0" friction="0.0"/>
	</joint> 




















	<link name="lidar_up">
		<visual>
			<geometry>
				<cylinder length="0.023" radius="0.01"/>
			</geometry>
		<material name="green">
			<color rgba="0.8 0.8 0.8 1"/>
		</material>
		</visual>
	</link>

	<joint name="lidar_up_joint" type="fixed">
		<parent link="base_link"/>
		<child link="lidar_up"/>
		<origin xyz="-0.100 0 0.172"/>
	</joint>
</robot>

